KeyError                                  Traceback (most recent call last)
File C:\ProgramData\anaconda3\lib\site-packages\pandas\core\indexes\base.py:3802, in Index.get_loc(self, key, method, tolerance)
   3801 try:
-> 3802     return self._engine.get_loc(casted_key)
   3803 except KeyError as err:

File C:\ProgramData\anaconda3\lib\site-packages\pandas\_libs\index.pyx:138, in pandas._libs.index.IndexEngine.get_loc()

File C:\ProgramData\anaconda3\lib\site-packages\pandas\_libs\index.pyx:165, in pandas._libs.index.IndexEngine.get_loc()

File pandas\_libs\hashtable_class_helper.pxi:5745, in pandas._libs.hashtable.PyObjectHashTable.get_item()

File pandas\_libs\hashtable_class_helper.pxi:5753, in pandas._libs.hashtable.PyObjectHashTable.get_item()

KeyError: 'math_score'

The above exception was the direct cause of the following exception:

KeyError                                  Traceback (most recent call last)
Cell In[18], line 21
     18 total_budget = schools_df['budget'].sum()
     20 # calculate the average maths score
---> 21 avg_math_score = students_df['math_score'].mean()
     23 # calculate the average reading score
     24 avg_reading_score = students_df['reading_score'].mean()

File C:\ProgramData\anaconda3\lib\site-packages\pandas\core\frame.py:3807, in DataFrame.__getitem__(self, key)
   3805 if self.columns.nlevels > 1:
   3806     return self._getitem_multilevel(key)
-> 3807 indexer = self.columns.get_loc(key)
   3808 if is_integer(indexer):
   3809     indexer = [indexer]

File C:\ProgramData\anaconda3\lib\site-packages\pandas\core\indexes\base.py:3804, in Index.get_loc(self, key, method, tolerance)
   3802     return self._engine.get_loc(casted_key)
   3803 except KeyError as err:
-> 3804     raise KeyError(key) from err
   3805 except TypeError:
   3806     # If we have a listlike key, _check_indexing_error will raise
   3807     #  InvalidIndexError. Otherwise we fall through and re-raise
   3808     #  the TypeError.
   3809     self._check_indexing_error(key)

KeyError: 'math_score'
